Workbook

Sheet Nacionalizado
A1: Somos G2E. Una empresa de energias renovables con mas de 15 años de experiencia en el sector. CONTACTANOS POR WHATSAPP AL: 11-3652-0821 Direccion comercial y administrativa: Vedia 3892, CABA, Argentina. NO VENDEMOS A USUARIO FINAL. NO VENDEMOS REPUESTOS NI DAMOS SERVICE A EQUIPOS DE TERCEROS . ESTE LISTADO DE PRECIOS ES PARA INSTALADORES / INTEGRADORES | E1: www.g2e.com.ar
A2: LEGAJO IMPOSITIVO
A3: CONDICIONES COMERCIALES: 1)Tipo de cambio: BNA billete vendedor del momento del pago 2)Forma de pago: Transferencia o depositos por ventanilla. Echeq al dia en casos previamente acordados. Tomamos pagos en USD (deposito en BNA o transferencia, ambos sin recargo) Echeq a 30 y 60 dias para clientes con historial de compra con tasa de recargo aproximada del 3,5% (a 30) a definir segun operacion. 3)Entrega: 3 a 5 dias habiles desde acreditado el pago para despachar en transporte en CABA. Se puede retirar por deposito dependiendo el producto. 4)IVA: Precios expresados sin IVA. 5)Stock: Confirmar stock previamente por whatsap. 6) Garantia: todos los productos cuentan con garantia. La garantia se hace efectiva con el equipo enviado a nuestros laboratorios en CABA. 7) Minimo de compra: USD 1000 + IVA
A4: Ultimas actualizaciones | C4: 06/5: ingresan hibridos DEYE y algunos con disminucion de precios. Ingresan baterias DEYE F12 y F16
C5: 11/5: reduccion precio huawei 150kw
C6: 12/5: ingresa jinko bifacial 620w buen precio
C7: 13/5: Opcion de impo contenedor entero de paneles a pedido. Consultar
C8: 22/5: ingresa estructura coplanar sunsolar
C9: 27/5: ingresn paneles jino y ja solar en buen precio minimo 3 pallet
C10: 01/06: aviso de aumento de paneles desde china
C11: 01/06: NOVEDAD INGRESAN INVERSORES ON GRID SUNGROW
C12: 03/06: poco stock baterias pro b de deye
C13: 08/06: ingresa bateria HOPE 16.0 (16KWH) compatible con inversores SPF
C14: 10/6: PANELES ASTROENERGY PRECIAZO X PALLET CERRADO EN LIQUIDACION
A23: Codigo | B23: DISPONIBILIDAD TENTATIVA. STOCK Y PRECIO A CONFIRMAR POR WHATSAPP | C23: PRODUCTO
A24: PANELES
A25: ='.'!A2 -> 1 | B25: ='.'!C2 -> INMEDIATO | C25: ='.'!D2 -> LONGI - 430w HiMOX6-LR5-54HTB (USD/watt) | D25: ='.'!F2 -> 0.23023256
A26: ='.'!A3 -> 2 | B26: ='.'!C3 -> INMEDIATO | C26: ='.'!D3 -> LONGI - 645w LR7-72HVH N-Type HPBC 2.0, HI-MO X10 (USD/watt) . se vende por unidad 15% mas caro. | D26: ='.'!F3 -> 0.1914 | E26: link de descarga
A27: ='.'!A4 -> 3 | B27: ='.'!C4 -> INMEDIATO | C27: ='.'!D4 -> LONGI - 610w BIFACIAL (USD/watt) - se vende por unidad 15% mas caro. | D27: 0.21 | E27: link de descarga
A28: ='.'!A5 -> 4 | B28: ='.'!C5 -> SIN FECHA ESTIMADA | C28: ='.'!D5 -> TRINA - BIFACIAL 570 (USD/watt).- se vende pallet cerrado | D28: ='.'!F5 -> 0.161 | E28: link de descarga
A29: ='.'!A6 -> 5 | B29: ='.'!C6 -> SIN FECHA ESTIMADA | C29: ='.'!D6 -> TRINA - BIFACIAL 605w TIPO N (USD/watt)- se vende pallet cerrado | D29: ='.'!F6 -> 0.161 | E29: link de descarga
A30: ='.'!A7 -> 6 | B30: ='.'!C7 -> INMEDIATO | C30: ='.'!D7 -> TRINA - BIFACIAL 615w TIPO N (USD/watt)- se vende pallet cerrado | D30: ='.'!F7 -> 0.1749
A31: ='.'!A8 -> 7 | B31: ='.'!C8 -> INMEDIATO | C31: ='.'!D8 -> TRINA - MONOFACIAL 620w TIPO N (USD/watt)- se vende pallet cerrado | D31: ='.'!F8 -> 0.1749
A32: ='.'!A9 -> 8 | B32: ='.'!C9 -> LIQUIDACION. Quedan 9 unidades | C32: ='.'!D9 -> TRINA - BIFACIAL 630w TIPO N (USD/watt)- se vende pallet cerrrado (o por unidad con costo de flete al transporte de usd 35+iva por entrega total) | D32: ='.'!F9 -> 0.165 | E32: link de descarga
A33: ='.'!A10 -> 9 | B33: ='.'!C10 -> INMEDIATO | C33: ='.'!D10 -> TRINA - MONOFACIAL 670w (USD/watt).- se vende pallet cerrado. Se entrega en transporte en Cordoba | D33: ='.'!F10 -> 0.1815 | E33: link de descarga
A34: ='.'!A11 -> 10 | B34: ='.'!C11 -> INMEDIATO | C34: ='.'!D11 -> TRINA - BIFACIAL 715 (USD/watt).- se vende pallet cerrado. Se retira por depo Soldati o va a transporte en CTC | D34: ='.'!F11 -> 0.1947 | E34: link de descarga
A35: ='.'!A12 -> 11 | B35: ='.'!C12 -> INMEDIATO | C35: ='.'!D12 -> JINKO - M/M 475w TIGER NEO JKM475-60HL4. se vende pallet cerrado o por unidad 30% mas caro | D35: 0.166 | E35: link de descarga
A36: ='.'!A13 -> 12 | B36: ='.'!C13 -> LIQUIDACION. Quedan 5 unidades | C36: ='.'!D13 -> JINKO - BIFACIAL 585 w 72HL4-BDV (USD/watt)- Se retiran por depo soldati | D36: ='.'!E13 -> 0.15 | E36: link de descarga
A37: ='.'!A14 -> 46034 | B37: ='.'!C14 -> INMEDIATO | C37: ='.'!D14 -> JINKO - MONOF 585 w 72HL4-BDV (USD/watt)- Se envia a transporte en Cordoba | D37: ='.'!F14 -> 0.18955
A38: ='.'!A15 -> 13 | B38: ='.'!C15 -> IMPO: 90 a 120 dias corridos | C38: ='.'!D15 -> JINKO - BIF 725 w TIPO N (USD/watt) se vende contenedor entero (20 pallet de 33 u) | D38: 0.15 | E38: link de descarga
A39: ='.'!A16 -> 14 | B39: ='.'!C16 -> INMEDIATO | C39: ='.'!D16 -> JINKO - BIFACIAL TIPO N, 620w(USD/watt)-se vende por unidad 32% mas caro. | D39: ='.'!F16 -> 0.17446 | E39: link de descarga
A40: ='.'!A17 -> 15 | B40: ='.'!C17 -> INMEDIATO | C40: ='.'!D17 -> JINKO - M/M TOPcon, 715w(USD/watt)-se vende palet cerrado | D40: ='.'!F17 -> 0.155 | E40: link de descarga
A41: ='.'!A18 -> 16 | B41: ='.'!C18 -> INMEDIATO | C41: ='.'!D18 -> JA SOLAR - BIFACIAL 600w - se vende pallet cerrado | D41: ='.'!F18 -> 0.155 | E41: link de descarga
A42: ='.'!A19 -> 17 | B42: ='.'!C19 -> INMEDIATO | C42: ='.'!D19 -> TRINA - BiFACIAL 620w TIPO N (USD/watt)-se vende pallet cerrado - | D42: ='.'!F19 -> 0.1749 | E42: link de descarga
A43: ='.'!A20 -> 18 | B43: ='.'!C20 -> INMEDIATO. 5 a 10 dias habiles para despachar | C43: ='.'!D20 -> LUXEN 144C. Mono Serie 4 410Wp PERC- se vende por unidad 2.5% mas caro (35mm) -5 a 10 dias habiles para despachar | D43: ='.'!F20 -> 0.16576
A44: ='.'!A21 -> 19 | B44: ='.'!C21 -> SIN FECHA ESTIMADA | C44: ='.'!D21 -> LUXEN 144C. Mono Serie 5 550Wp PERC (35mm)- se vende por unidad 2.5% mas caro - 5 a 10 dias habiles para despachar | D44: ='.'!F21 -> 0.16128
A45: ='.'!A22 -> 20 | B45: ='.'!C22 -> SIN FECHA ESTIMADA | C45: ='.'!D22 -> LUXEN - 144C. M/M . Serie 5 550Wp PERC BLACK (35mm)- se vende por unidad 2.5% mas caro - 5 a 10 dias habiles para despachar | D45: ='.'!F22 -> 0.165 | E45: link de descarga
A46: ='.'!A23 -> 21 | B46: ='.'!C23 -> INMEDIATO. Se vende por unidad | C46: ='.'!D23 -> LUXEN - 132C. M/M N5 585Wp TOPcon- se vende por unidad 2.5% mas caro - 5 a 10 dias habiles para despachar | D46: ='.'!F23 -> 0.1694 | E46: link de descarga
A47: ='.'!A24 -> 22 | B47: ='.'!C24 -> INMEDIATO. Se vende por unidad | C47: ='.'!D24 -> LUXEN - 132C. N5 RECT 585Wp TOPCon GoG bifacial - se vende por unidad 2.5% mas caro (36u x pallet) - 5 a 10 dias habiles para despachar | D47: ='.'!F24 -> 0.1694 | E47: link de descarga
A48: ='.'!A25 -> 23 | B48: ='.'!C25 -> INMEDIATO. Se vende por unidad | C48: ='.'!D25 -> LUXEN 144C. Mono N5 RECT 630Wp TOPCon- se vende por unidad 2.5% mas caro. - 5 a 10 dias habiles para despachar | D48: ='.'!F25 -> 0.1694 | E48: link de descarga
...

Sheet .
A2: 1 | B2: N | C2: INMEDIATO | D2: LONGI - 430w HiMOX6-LR5-54HTB (USD/watt) | E2: =Nacionalizado!D25 -> 0.23023256 | F2: =(90/430)*1.1 -> 0.23023256
A3: 2 | B3: N | C3: INMEDIATO | D3: LONGI - 645w LR7-72HVH N-Type HPBC 2.0, HI-MO X10 (USD/watt) . se vende por unidad 15% mas caro. | E3: =Nacionalizado!D26 -> 0.1914 | F3: =0.174*1.1 -> 0.1914
A4: 3 | B4: PC | C4: INMEDIATO | D4: LONGI - 610w BIFACIAL (USD/watt) - se vende por unidad 15% mas caro. | E4: =Nacionalizado!D27 -> 0.21 | F4: =0.16*1.1 -> 0.176
A5: 4 | B5: AR | C5: SIN FECHA ESTIMADA | D5: TRINA - BIFACIAL 570 (USD/watt).- se vende pallet cerrado | E5: =Nacionalizado!D28 -> 0.161 | F5: =0.14*1.15 -> 0.161
A6: 5 | B6: A | C6: SIN FECHA ESTIMADA | D6: TRINA - BIFACIAL 605w TIPO N (USD/watt)- se vende pallet cerrado | E6: =Nacionalizado!D29 -> 0.161 | F6: =0.14*1.15 -> 0.161
A7: 6 | B7: AM | C7: INMEDIATO | D7: TRINA - BIFACIAL 615w TIPO N (USD/watt)- se vende pallet cerrado | E7: =Nacionalizado!D30 -> 0.1749 | F7: =0.159*1.1 -> 0.1749
A8: 7 | B8: A | C8: INMEDIATO | D8: TRINA - MONOFACIAL 620w TIPO N (USD/watt)- se vende pallet cerrado | E8: =Nacionalizado!D31 -> 0.1749 | F8: =0.159*1.1 -> 0.1749
A9: 8 | B9: A | C9: LIQUIDACION. Quedan 9 unidades | D9: TRINA - BIFACIAL 630w TIPO N (USD/watt)- se vende pallet cerrrado (o por unidad con costo de flete al transporte de usd 35+iva por entrega total) | E9: =Nacionalizado!D32 -> 0.165 | F9: =0.15*1.1 -> 0.165 | G9: (+10RJ) -1 aristides -
A10: 9 | B10: 2 | C10: INMEDIATO | D10: TRINA - MONOFACIAL 670w (USD/watt).- se vende pallet cerrado. Se entrega en transporte en Cordoba | E10: =Nacionalizado!D33 -> 0.1815 | F10: =0.165*1.1 -> 0.1815
A11: 10 | B11: R | C11: INMEDIATO | D11: TRINA - BIFACIAL 715 (USD/watt).- se vende pallet cerrado. Se retira por depo Soldati o va a transporte en CTC | E11: =Nacionalizado!D34 -> 0.1947 | F11: =0.177*1.1 -> 0.1947
A12: 11 | B12: M | C12: INMEDIATO | D12: JINKO - M/M 475w TIGER NEO JKM475-60HL4. se vende pallet cerrado o por unidad 30% mas caro | E12: =Nacionalizado!D35 -> 0.166 | F12: =0.222*1.1 -> 0.2442
A13: 12 | B13: S | C13: LIQUIDACION. Quedan 5 unidades | D13: JINKO - BIFACIAL 585 w 72HL4-BDV (USD/watt)- Se retiran por depo soldati | E13: 0.15 | F13: =0.145*1.11 -> 0.16095 | G13: (+5RJ)
A14: 46034 | C14: INMEDIATO | D14: JINKO - MONOF 585 w 72HL4-BDV (USD/watt)- Se envia a transporte en Cordoba | E14: =Nacionalizado!D37 -> 0.18955 | F14: =0.17*1.115 -> 0.18955
A15: 13 | B15: S | C15: IMPO: 90 a 120 dias corridos | D15: JINKO - BIF 725 w TIPO N (USD/watt) se vende contenedor entero (20 pallet de 33 u) | E15: 0.16 | F15: =0.151*1.1 -> 0.1661
A16: 14 | B16: B | C16: INMEDIATO | D16: JINKO - BIFACIAL TIPO N, 620w(USD/watt)-se vende por unidad 32% mas caro. | E16: =Nacionalizado!D39 -> 0.17446 | F16: =0.1586*1.1 -> 0.17446
A17: 15 | B17: 2 | C17: INMEDIATO | D17: JINKO - M/M TOPcon, 715w(USD/watt)-se vende palet cerrado | E17: =Nacionalizado!D40 -> 0.155 | F17: =0.155 -> 0.155
A18: 16 | C18: INMEDIATO | D18: JA SOLAR - BIFACIAL 600w - se vende pallet cerrado | E18: =Nacionalizado!D41 -> 0.155 | F18: =0.155 -> 0.155
A19: 17 | B19: A | C19: INMEDIATO | D19: TRINA - BiFACIAL 620w TIPO N (USD/watt)-se vende pallet cerrado - | E19: =Nacionalizado!D42 -> 0.1749 | F19: =0.159*1.1 -> 0.1749
A20: 18 | C20: INMEDIATO. 5 a 10 dias habiles para despachar | D20: LUXEN 144C. Mono Serie 4 410Wp PERC- se vende por unidad 2.5% mas caro (35mm) -5 a 10 dias habiles para despachar | E20: =Nacionalizado!D43 -> 0.16576 | F20: =0.148*1.12 -> 0.16576
A21: 19 | C21: SIN FECHA ESTIMADA | D21: LUXEN 144C. Mono Serie 5 550Wp PERC (35mm)- se vende por unidad 2.5% mas caro - 5 a 10 dias habiles para despachar | E21: =Nacionalizado!D44 -> 0.16128 | F21: =0.144*1.12 -> 0.16128
A22: 20 | C22: SIN FECHA ESTIMADA | D22: LUXEN - 144C. M/M . Serie 5 550Wp PERC BLACK (35mm)- se vende por unidad 2.5% mas caro - 5 a 10 dias habiles para despachar | E22: =Nacionalizado!D45 -> 0.165 | F22: =0.15*1.1 -> 0.165
A23: 21 | C23: INMEDIATO. Se vende por unidad | D23: LUXEN - 132C. M/M N5 585Wp TOPcon- se vende por unidad 2.5% mas caro - 5 a 10 dias habiles para despachar | E23: =Nacionalizado!D46 -> 0.1694 | F23: =0.154*1.1 -> 0.1694
A24: 22 | C24: INMEDIATO. Se vende por unidad | D24: LUXEN - 132C. N5 RECT 585Wp TOPCon GoG bifacial - se vende por unidad 2.5% mas caro (36u x pallet) - 5 a 10 dias habiles para despachar | E24: =Nacionalizado!D47 -> 0.1694 | F24: =0.154*1.1 -> 0.1694
A25: 23 | C25: INMEDIATO. Se vende por unidad | D25: LUXEN 144C. Mono N5 RECT 630Wp TOPCon- se vende por unidad 2.5% mas caro. - 5 a 10 dias habiles para despachar | E25: =Nacionalizado!D48 -> 0.1694 | F25: =0.154*1.1 -> 0.1694
A26: 24 | C26: INMEDIATO. Se vende por unidad | D26: LUXEN - 132C. Mono N6 700Wp TOPCon GoG Bifacial- se vende por unidad 2.5% mas caro (34u x pallet) - 5 a 10 dias habiles para despachar | E26: =Nacionalizado!D49 -> 0.1694 | F26: =0.154*1.1 -> 0.1694
A27: 25 | B27: 1 | C27: LIQUIDACION PALLET CERRADO | D27: ASTROENERGY - BIFACIAL 144 CEL. N TYPE 575W CABLE 1.4M. Se vende pallet cerrado. Se entrega en transporte en Cordoba | E27: 0.15 | F27: =0.165*1.1 -> 0.1815
A28: 26 | C28: LIQUIDACION. Quedan 2 unidades | D28: ASTROENERGY - BIFACIAL 144 CEL. N TYPE 585W - se vende por unidad. Se entrega en depo soldati u oficina DOT | E28: 0.14 | G28: (+1RJ)(+1 DOT)
A29: 27 | B29: M | C29: INMEDIATO | D29: ASTROENERGY - 615w -N7_CHSM66RN(DG)F-BH dual glass - BIFACIAL. Se retira por depo Soldati | E29: =Nacionalizado!D52 -> 0.22357724 | F29: =125/615*1.1 -> 0.22357724
A30: 28 | B30: CB | C30: SIN FECHA ESTIMADA | D30: AMERISOLAR- Policristalino 340w. Pallet 36 unidades. se vende pallet cerrado | E30: =Nacionalizado!D53 -> 0.28336 | F30: =0.23*1.12*1.1 -> 0.28336
A31: 29 | B31: BC | C31: SIN FECHA ESTIMADA | D31: AMERISOLAR - MONOCRISTALINO AS-7M108N-HC-440W. se vende por unidad 32% mas caro. 36u x pallet -Entrega gratis en GBA. | E31: =Nacionalizado!D54 -> 0.187 | F31: =0.17*1.1 -> 0.187
A32: 30 | B32: BCV | C32: SIN FECHA ESTIMADA | D32: AMERISOLAR - MONOCRISTALINO AS-7M144-HC-555W. se vende por unidad 32% mas caro. -Entrega gratis en GBA. | E32: =Nacionalizado!D55 -> 0.1668106 | F32: =0.121*1.22*1.13 -> 0.1668106
A33: 31 | B33: BC | C33: INMEDIATO. Se vende por unidad | D33: AMERISOLAR - MONOCRISTALINO AS-7M144-HC-580W. precio pallet cerrado. Entrega gratis en GBA. Por unidad 30% mas caro | E33: =Nacionalizado!D56 -> 0.15859218 | F33: =(88.83/580)*0.95*1.09 -> 0.15859218
A34: 32 | B34: CB | C34: SIN FECHA ESTIMADA | D34: AMERISOLAR - MONOCRISTALINO AS-8M120-HC-600W. se vende por unidad 30% mas caro. | E34: =Nacionalizado!D57 -> 0.14 | F34: =0.125*1.12 -> 0.14
A35: 33 | C35: INMEDIATO. Quedan 28 unidades se venden juntas | D35: SUNPRO - Monoc, TOPCON, SPDG585-N144M10-585W con Marco Negro. BIFACIAL. se venden las 28 unidades juntas | E35: =Nacionalizado!D58 -> 0.1595 | F35: =0.145*1.1 -> 0.1595
A36: 34 | C36: INMEDIATO | D36: HAITAI - Monocristalino, media celda, Anti LID HTM585DMH5-72NT-585W. Pallet 36 unidades. se vende por unidad 32% mas caro. | E36: =Nacionalizado!D59 -> 0.17504197 | F36: =(97.99/585)*0.95*1.1 -> 0.17504197
A37: 35 | C37: INGRESA ABRIL | D37: HAITAI - Monocristalino, media celda, HTM415MH5-54 415W. Pallet 36 unidades. se vende por unidad 32% mas caro. | E37: =Nacionalizado!D60 -> 0.1495 | F37: =0.115*1.3 -> 0.1495
A38: 36 | C38: INMEDIATO | D38: HAITAI, Monocristalino, media celda, Anti LID, Bifacial, HTM630DMH6-66NT BIFACIAL 630W. Pallet 36 unidades.se vende por unidad 32% mas caro | E38: =Nacionalizado!D61 -> 0.1826 | F38: =0.166*1.1 -> 0.1826
A39: 37 | C39: INMEDIATO | D39: TLC - Anti LID TCL-MI585 DH182-72NT 585W BIFACIAL. Pallet 36 unidades. se vende por unidad 32% mas caro | E39: =Nacionalizado!D62 -> 0.16264487 | F39: =(91.05/585)*0.95*1.1 -> 0.16264487
A40: 38 | C40: INMEDIATO | D40: NUUKO - monof 550w (pallet 31 u) - se vende minimo 10 u | E40: =Nacionalizado!D63 -> 0.161
A41: 39 | C41: INMEDIATO | D41: NUUKO - bif 615w topcon (pallet 36 u) - se vende minimo 10 u | E41: =Nacionalizado!D64 -> 0.169
...
